File: silicone_10a/oct_22/data/Test7.Stop.csv
"Total Time (s)","Cycle Elapsed Time (s)","Total Cycles","Elapsed Cycles","Step","Total Cycle Count(Linear Waveform)","Total Cycle Count(Rotary Waveform)","Position (mm)","Force (kN)","Stress (MPa)","Digital Position (mm)","Rotation (deg)","Torque (N·m)","Digital Rotation (deg)",
8.401,0,43,43,1,42,0,1.40528200152933,-0.00799660896376963,-7.99660896376963,1.40528578152933,-33.1310006943432,0.0266326081388442,-33.1309982481685,
8.411,0.00999999999999979,43,43,1,42,0,0.434617483019421,-0.00572093108052831,-5.72093108052831,0.434621263019421,-33.1338998927816,0.0178230384570916,-33.1338974466068,
8.419,0.0180000000000007,43,43,1,42,0,0.184605524728693,-0.00650617556133843,-6.50617556133843,0.184609304728693,-33.1368172890157,0.0264193377352929,-33.136814842841,
8.429,0.0280000000000005,43,43,1,42,0,0.489259577125566,-0.0064539065505289,-6.4539065505289,0.489263357125565,-33.1384533869249,0.0203120455631282,-33.1384509407502,
8.44,0.0389999999999997,43,43,1,42,0,1.62098399024177,-0.00737847227411394,-7.37847227411394,1.62098777024177,-33.1377130834702,0.0249138648710782,-33.1377106372954,
8.45,0.0489999999999995,43,43,1,42,0,3.31897642309089,-0.010017364681403,-10.017364681403,3.3189802030909,-33.1330061860603,0.0214952554415142,-33.1330037398856,
8.46,0.0590000000000011,43,43,1,42.25,0,5.47350182475404,-0.0153887941699069,-15.3887941699069,5.47350560475405,-33.1274827677353,0.0142233777759171,-33.1274803215606,
8.469,0.0679999999999996,43,43,1,42.25,0,7.55052135482703,-0.0174559751937463,-17.4559751937463,7.55052513482703,-33.1258666346328,0.0136826028895571,-33.1258641884581,
8.478,0.077,43,43,1,42.25,0,9.62923122261128,-0.0203465162433823,-20.3465162433823,9.62923500261125,-33.1262468529708,0.0190525515504243,-33.126244406796,
8.488,0.0869999999999997,43,43,1,42.25,0,11.7733034324681,-0.0235943247416814,-23.5943247416814,11.7733072124681,-33.1300872585567,0.0261411422078545,-33.1300848123819,
8.498,0.0969999999999995,43,43,1,42.25,0,13.523485268669,-0.0269569728611672,-26.9569728611672,13.523489048669,-33.1334553459158,0.0207074413502703,-33.1334528997411,
8.508,0.107000000000001,43,43,1,42.5,0,14.6985513746182,-0.0291276623368182,-29.1276623368182,14.6985551546182,-33.1336102398389,0.0189450647732636,-33.1336077936641,
8.517,0.116,43,43,1,42.5,0,15.1608747399777,-0.02988439120101,-29.88439120101,15.1608785199777,-33.1321737988148,0.0204126073545534,-33.13217135264,
8.527,0.126000000000001,43,43,1,42.5,0,15.035686482649,-0.027572739530547,-27.572739530547,15.035690262649,-33.1308662542632,0.022413277079102,-33.1308638080885,
8.537,0.136000000000001,43,43,1,42.5,0,14.2874355110538,-0.0289937785755115,-28.9937785755115,14.2874392910538,-33.1322795670333,0.0219513131249432,-33.1322771208586,
8.547,0.146000000000001,43,43,1,42.5,0,12.8401037668729,-0.0277471407740423,-27.7471407740423,12.8401075468729,-33.1331020713413,0.022396557649467,-33.1330996251666,
8.557,0.156000000000001,43,43,1,42.75,0,10.8205318891761,-0.0237862009626018,-23.7862009626018,10.8205356691761,-33.1333833669015,0.0219172396077996,-33.1333809207267,
8.567,0.166,43,43,1,42.75,0,8.4506702182815,-0.0185960052920772,-18.5960052920772,8.45067399828149,-33.1354120603523,0.0242592908375626,-33.1354096141776,
8.577,0.176,43,43,1,42.75,0,6.00402902494548,-0.0143817960767324,-14.3817960767324,6.00403280494548,-33.1341355345671,0.0186154032182608,-33.1341330883924,
8.587,0.186,43,43,1,42.75,0,3.77742766186218,-0.0113750680951511,-11.3750680951511,3.77743144186217,-33.1318284329741,0.0179633745478611,-33.1318259867993,
8.597,0.196,43,43,1,42.75,0,1.97329608224372,-0.00901130016132275,-9.01130016132275,1.97329986224372,-33.1313794171196,0.0215498779992256,-33.1313769709448,
8.607,0.00599999999999845,44,44,1,43,0,0.730800150002885,-0.00636833249054844,-6.36833249054844,0.730803930002886,-33.1330048433286,0.0230924263074187,-33.1330023971538,
8.616,0.0149999999999988,44,44,1,43,0,0.212258856392713,-0.00595240641918061,-5.95240641918061,0.212262636392713,-33.1353017344687,0.0242379692301627,-33.1352992882939,
8.625,0.0239999999999991,44,44,1,43,0,0.27733739427681,-0.00732787686149121,-7.32787686149121,0.27734117427681,-33.1385207980348,0.0230903571898651,-33.1385183518601,
8.635,0.0339999999999989,44,44,1,43,0,0.997896330094779,-0.0068268326554679,-6.8268326554679,0.99790011009478,-33.1392964012998,0.0198336005730454,-33.1392939551251,
8.645,0.0439999999999987,44,44,1,43,0,2.39574822729103,-0.00815255691779522,-8.15255691779522,2.39575200729103,-33.1356951380329,0.0199292167622422,-33.1356926918581,
8.655,0.0539999999999985,44,44,1,43.25,0,4.35791779506762,-0.012274496088214,-12.274496088214,4.35792157506763,-33.1287515999412,0.0199745133842812,-33.1287491537665,
8.665,0.0640000000000001,44,44,1,43.25,0,6.62852006104708,-0.0177486306070823,-17.7486306070823,6.62852384104709,-33.1255409333703,0.0285660887996025,-33.1255384871956,
8.673,0.0719999999999992,44,44,1,43.25,0,8.48570457639667,-0.0183340333648617,-18.3340333648617,8.48570835639667,-33.1268950983297,0.0181160123076223,-33.1268926521549,
8.683,0.081999999999999,44,44,1,43.25,0,10.7494829537142,-0.0224516140388901,-22.4516140388901,10.7494867337142,-33.1311764297775,0.0220223405544247,-33.1311739836028,
8.693,0.0919999999999987,44,44,1,43.25,0,12.7222902327528,-0.025682683799803,-25.682683799803,12.7222940127528,-33.1336198656928,0.0272873181622266,-33.1336174195181,
8.703,0.101999999999999,44,44,1,43.5,0,14.1971186402054,-0.0279095710514611,-27.9095710514612,14.1971224202054,-33.1334707598385,0.0221185430479404,-33.1334683136637,
8.713,0.112,44,44,1,43.5,0,15.034844202465,-0.0302338465512098,-30.2338465512098,15.034847982465,-33.1324576586915,0.021389900979365,-33.1324552125167,
8.721,0.119999999999999,44,44,1,43.5,0,15.176080651672,-0.025865554805014,-25.865554805014,15.176084431672,-33.1319387399134,0.0213628849692895,-33.1319362937388,
8.731,0.129999999999999,44,44,1,43.5,0,14.817534406843,-0.0290187157948958,-29.0187157948958,14.817538186843,-33.1323950505175,0.0180162820571911,-33.1323926043428,
8.741,0.139999999999999,44,44,1,43.5,0,13.7793273885749,-0.0289295088471929,-28.9295088471929,13.7793311685749,-33.1328005702876,0.0240650012374898,-33.1327981241128,
8.751,0.149999999999999,44,44,1,43.75,0,12.0746752787058,-0.0257656098406412,-25.7656098406412,12.0746790587058,-33.1339176387687,0.0248072067045071,-33.1339151925939,
8.761,0.16,44,44,1,43.75,0,9.88740180948095,-0.0222288837636904,-22.2288837636904,9.88740558948094,-33.1355389099564,0.0194201171871003,-33.1355364637817,
8.771,0.17,44,44,1,43.75,0,7.45813604924258,-0.0174210471817954,-17.4210471817954,7.45813982924258,-33.1371519486158,0.0224240483284326,-33.1371495024411,
8.781,0.18,44,44,1,43.75,0,5.06342263031632,-0.0114034286189859,-11.4034286189859,5.06342641031631,-33.1334981226477,0.0166181092007012,-33.1334956764729,
8.791,0.19,44,44,1,43.75,0,3.00127948460915,-0.0107343217051084,-10.7343217051084,3.00128326460915,-33.1308280881295,0.0221856961115269,-33.1308256419547,
8.801,0.199999999999999,44,44,1,44,0,1.40424456534641,-0.00777518746120236,-7.77518746120236,1.40424834534641,-33.132026462183,0.0267444984417147,-33.1320240160082,
8.811,0.00999999999999979,45,45,1,44,0,0.433058843701985,-0.00586447040183941,-5.86447040183941,0.433062623701984,-33.1337898987429,0.0216205887373516,-33.1337874525681,
8.821,0.0199999999999996,45,45,1,44,0,0.191091899757116,-0.00796875928289148,-7.96875928289148,0.191095679757116,-33.1361021191843,0.0175875451290404,-33.1360996730096,
8.83,0.0289999999999999,45,45,1,44,0,0.555390726957176,-0.0067456980390313,-6.7456980390313,0.555394506957177,-33.1370674964316,0.0206388548382906,-33.1370650502569,
8.84,0.0389999999999997,45,45,1,44,0,1.61988379173794,-0.00720132764827292,-7.20132764827292,1.61988757173794,-33.1352857282894,0.0206799676006632,-33.1352832821147,
8.85,0.0489999999999995,45,45,1,44,0,3.31861856832649,-0.0100288425819779,-10.0288425819779,3.31862234832649,-33.13128295919,0.0249584318140133,-33.1312805130153,
8.86,0.0589999999999993,45,45,1,44.25,0,5.47030805304687,-0.0155112189917472,-15.5112189917472,5.47031183304687,-33.12680268352,0.0182617200545044,-33.1268002373452,
8.87,0.0690000000000008,45,45,1,44.25,0,7.77867080978578,-0.0175984108587555,-17.5984108587555,7.77867458978577,-33.1255375344855,0.016490453534232,-33.1255350883107,
8.88,0.0790000000000006,45,45,1,44.25,0,10.0839742471879,-0.0215699643227187,-21.5699643227187,10.0839780271879,-33.1271375387551,0.0242114268514485,-33.1271350925803,
8.89,0.0890000000000004,45,45,1,44.25,0,12.1684211331553,-0.0245312464381291,-24.5312464381291,12.1684249131554,-33.132473128254,0.0250285498180959,-33.1324706820794,
8.9,0.0990000000000002,45,45,1,44.25,0,13.8132717850806,-0.0274687331885171,-27.4687331885171,13.8132755650806,-33.1347738862872,0.0221854133876276,-33.1347714401126,
8.91,0.109,45,45,1,44.5,0,14.8578093874398,-0.0296741430454059,-29.6741430454059,14.8578131674398,-33.1339319253775,0.0234851829698403,-33.1339294792028,
8.919,0.118,45,45,1,44.5,0,15.1844945964958,-0.0289398555451326,-28.9398555451326,15.1844983764958,-33.1312255290111,0.0212319946442008,-33.1312230828363,
8.929,0.128,45,45,1,44.5,0,14.9422140966659,-0.0285356380625954,-28.5356380625954,14.9422178766658,-33.1304954559233,0.0203481889571429,-33.1304930097485,
8.939,0.138,45,45,1,44.5,0,14.0469290820481,-0.028757455996871,-28.757455996871,14.0469328620481,-33.132174084941,0.023275149167183,-33.1321716387662,
8.949,0.148,45,45,1,44.5,0,12.4667776829995,-0.0270035896470678,-27.0035896470678,12.4667814629995,-33.1325320942914,0.024719670215545,-33.1325296481166,
8.959,0.157999999999999,45,45,1,44.75,0,10.3570877924078,-0.0234827339788677,-23.4827339788677,10.3570915724078,-33.1334899943437,0.0228381241250102,-33.1334875481689,
8.969,0.167999999999999,45,45,1,44.75,0,7.95056434477139,-0.0180158257143838,-18.0158257143838,7.95056812477138,-33.1346298796115,0.0199686288281756,-33.1346274334368,
8.979,0.178000000000001,45,45,1,44.75,0,5.52343577199653,-0.0130363415025749,-13.0363415025749,5.52343955199654,-33.1330358468312,0.0248212003125714,-33.1330334006564,
8.989,0.188000000000001,45,45,1,44.75,0,3.37732085524835,-0.0110625509251966,-11.0625509251966,3.37732463524835,-33.1316270336138,0.0304684936433534,-33.131624587439,
8.999,0.198,45,45,1,44.75,0,1.67513510243387,-0.00827241113877274,-8.27241113877274,1.67513888243387,-33.1290756021055,0.0177019594957302,-33.1290731559308,
9.009,0.0080000000000009,46,46,1,45,0,0.567599521399681,-0.00607197765896741,-6.07197765896741,0.567603301399681,-33.1314744904775,0.018541878000985,-33.1314720443027,
9.018,0.0170000000000012,46,46,1,45,0,0.183331163013945,-0.00609022659719735,-6.09022659719735,0.183334943013944,-33.1356867681648,0.0203608386425174,-33.1356843219901,
9.027,0.0260000000000016,46,46,1,45,0,0.365976349424761,-0.00662013632565314,-6.62013632565314,0.36598012942476,-33.1373686022362,0.0185245060585737,-33.1373661560613,
9.037,0.0360000000000014,46,46,1,45,0,1.22617170571457,-0.00745069961836416,-7.45069961836416,1.22617548571457,-33.1364854366349,0.0237405268750657,-33.1364829904602,
9.047,0.0460000000000012,46,46,1,45,0,2.74581726788181,-0.00882893877540878,-8.82893877540878,2.7458210478818,-33.1312686595782,0.0213555377656158,-33.1312662134035,
9.057,0.0560000000000009,46,46,1,45.25,0,4.79415305598005,-0.0136018846743238,-13.6018846743238,4.79415683598004,-33.1269033781994,0.0199295479829466,-33.1269009320247,
9.067,0.0660000000000007,46,46,1,45.25,0,7.08908546191223,-0.0173358028284105,-17.3358028284105,7.08908924191223,-33.1265112784336,0.0230087138018552,-33.1265088322589,
9.077,0.0760000000000005,46,46,1,45.25,0,9.4124084420972,-0.0198058374943509,-19.8058374943509,9.41241222209718,-33.1272096189755,0.020314561216291,-33.1272071728008,
9.087,0.0860000000000003,46,46,1,45.25,0,11.5853731447709,-0.0229658548621581,-22.9658548621581,11.5853769247709,-33.1303461495897,0.0223821354591893,-33.130343703415,
9.097,0.0960000000000001,46,46,1,45.25,0,13.3826082514292,-0.0267806637100845,-26.7806637100845,13.3826120314292,-33.1328647977122,0.0242835035503801,-33.1328623515374,
9.107,0.106,46,46,1,45.5,0,14.6162608759993,-0.0289328317403288,-28.9328317403288,14.6162646559993,-33.1342406785889,0.0221431467645447,-33.1342382324142,
9.117,0.116000000000001,46,46,1,45.5,0,15.1633022206572,-0.0299397991533031,-29.9397991533031,15.1633060006572,-33.1330534806765,0.0220100340229176,-33.1330510345017,
9.127,0.126000000000001,46,46,1,45.5,0,15.0323428714577,-0.0275373622128525,-27.5373622128525,15.0323466514577,-33.1325411900102,0.0227821401011619,-33.1325387438355,
9.137,0.136000000000001,46,46,1,45.5,0,14.2755852796015,-0.028910198687604,-28.910198687604,14.2755890596015,-33.1332561223037,0.02158427728029,-33.1332536761289,
9.147,0.146000000000001,46,46,1,45.5,0,12.8239643724168,-0.0277538115323696,-27.7538115323696,12.8239681524168,-33.1332585656237,0.0208543296954095,-33.1332561194491,
9.157,0.156000000000001,46,46,1,45.75,0,10.8020355171026,-0.0235902494241889,-23.5902494241889,10.8020392971026,-33.1350110671116,0.0190067386153368,-33.1350086209368,
9.167,0.166,46,46,1,45.75,0,8.43479272480102,-0.0185037631946194,-18.5037631946194,8.43479650480101,-33.1374328157476,0.0259042766181582,-33.1374303695729,
9.176,0.175000000000001,46,46,1,45.75,0,6.2337269374603,-0.0153905643533132,-15.3905643533132,6.23373071746029,-33.1347154705821,0.0246617297056828,-33.1347130244074,
9.185,0.184000000000001,46,46,1,45.75,0,4.18580454434611,-0.0113112173475296,-11.3112173475296,4.18580832434612,-33.1315365299596,0.0232675535902737,-33.1315340837849,
9.195,0.194000000000001,46,46,1,45.75,0,2.29654655045328,-0.00962564077937555,-9.62564077937555,2.29655033045327,-33.1311448560995,0.0239368611608009,-33.1311424099248,
9.205,0.00399999999999956,47,47,1,46,0,0.932388515479848,-0.00690254113649925,-6.90254113649925,0.932392295479849,-33.1329660345674,0.0210233934947137,-33.1329635883926,
9.215,0.0139999999999993,47,47,1,46,0,0.249732191325013,-0.0060020362602139,-6.0020362602139,0.249735971325013,-33.135070878091,0.0209098217082648,-33.1350684319162,
9.225,0.0239999999999991,47,47,1,46,0,0.286443021721324,-0.00720971623042231,-7.2097162304223,0.286446801721323,-33.1373135558343,0.0231558447464093,-33.1373111096596,
9.235,0.0339999999999989,47,47,1,46,0,1.00355494885561,-0.00686326420207735,-6.86326420207735,1.00355872885562,-33.1371481772359,0.0195587648297134,-33.1371457310612,
9.245,0.0440000000000005,47,47,1,46,0,2.39797970098492,-0.00804572802531506,-8.04572802531506,2.39798348098492,-33.1332233807814,0.0201673569894861,-33.1332209346066,
9.255,0.0540000000000003,47,47,1,46.25,0,4.35529255254014,-0.0121990375174823,-12.1990375174823,4.35529633254013,-33.1272530937194,0.0223454558569946,-33.1272506475447,
9.264,0.0629999999999988,47,47,1,46.25,0,6.39086591448538,-0.017558357628451,-17.558357628451,6.39086969448538,-33.1251265889784,0.0230389121509181,-33.1251241428037,
9.273,0.0719999999999992,47,47,1,46.25,0,8.47550033562121,-0.0180077998595504,-18.0077998595504,8.4755041156212,-33.1257323546239,0.0178822229582903,-33.1257299084491,
9.283,0.081999999999999,47,47,1,46.25,0,10.7386346892539,-0.0223275022716291,-22.3275022716291,10.7386384692539,-33.1287627896225,0.0224366155505728,-33.1287603434477,
9.293,0.0920000000000005,47,47,1,46.25,0,12.7129197557421,-0.0257616448471258,-25.7616448471258,12.7129235357421,-33.1321133248656,0.0259099962630408,-33.1321108786909,
9.303,0.102,47,47,1,46.5,0,14.1899495928349,-0.0277521822638379,-27.7521822638379,14.1899533728349,-33.1334356112484,0.0248193200415085,-33.1334331650736,
9.313,0.112,47,47,1,46.5,0,15.0297651131543,-0.0302210953102637,-30.2210953102637,15.0297688931543,-33.1328375608987,0.0208011634094873,-33.132835114724,
9.323,0.122,47,47,1,46.5,0,15.1441956362558,-0.0247620130872556,-24.7620130872556,15.1441994162558,-33.1313931639847,0.0212971342457951,-33.1313907178099,
9.333,0.132,47,47,1,46.5,0,14.6660523545397,-0.0289614327288427,-28.9614327288427,14.6660561345397,-33.1317068184662,0.0227574024855531,-33.1317043722914,
9.343,0.141999999999999,47,47,1,46.5,0,13.4901370758434,-0.0286490199266066,-28.6490199266066,13.4901408558434,-33.1329614087522,0.0215339587319998,-33.1329589625775,
9.353,0.151999999999999,47,47,1,46.75,0,11.6721076675702,-0.0250086322144521,-25.0086322144521,11.6721114475702,-33.1324113785186,0.0243273067751996,-33.1324089323438,
9.363,0.161999999999999,47,47,1,46.75,0,9.41305413342473,-0.0207132996768036,-20.7132996768036,9.41305791342473,-33.1339914484406,0.0201976153927675,-33.1339890022659,
9.373,0.171999999999999,47,47,1,46.75,0,6.96821405442755,-0.0167192264140217,-16.7192264140217,6.96821783442754,-33.1345703004208,0.0186095089573525,-33.1345678542461,
9.382,0.180999999999999,47,47,1,46.75,0,4.83810377115546,-0.0113223198456844,-11.3223198456844,4.83810755115547,-33.132405602153,0.0204343470963083,-33.1324031559783,
9.392,0.190999999999999,47,47,1,46.75,0,2.81731753429696,-0.0105360406765141,-10.5360406765141,2.81732131429696,-33.1302154480075,0.0253159098070927,-33.1302130018327,
9.401,0.199999999999999,47,47,1,47,0,1.40322548154801,-0.00780577056610003,-7.80577056610003,1.40322926154802,-33.1293856286844,0.0251893419576963,-33.1293831825097,
9.411,0.00999999999999979,48,48,1,47,0,0.431047028507528,-0.00601935697171534,-6.01935697171534,0.431050808507528,-33.1325886913141,0.0200273242870526,-33.1325862451394,
9.421,0.0199999999999996,48,48,1,47,0,0.187783397073266,-0.00805222595425464,-8.05222595425464,0.187787177073266,-33.1366893748401,0.0187710932159734,-33.1366869286654,
9.431,0.0300000000000011,48,48,1,47,0,0.625934371574362,-0.00657334731328595,-6.57334731328595,0.625938151574362,-33.1386962944643,0.0247878170335845,-33.1386938482896,
9.441,0.0400000000000009,48,48,1,47,0,1.757189879335,-0.00724012512260512,-7.24012512260512,1.757193659335,-33.1361870187525,0.0203184815999181,-33.1361845725777,
9.451,0.0500000000000007,48,48,1,47.25,0,3.51362378611415,-0.010254973485639,-10.254973485639,3.51362756611416,-33.1308205943277,0.0210457364063579,-33.130818148153,
9.461,0.0600000000000005,48,48,1,47.25,0,5.69784200565862,-0.0161706635285728,-16.1706635285728,5.69784578565862,-33.1259930552673,0.0268416779828644,-33.1259906090926,
9.471,0.0700000000000003,48,48,1,47.25,0,8.01044934458761,-0.0177849776456127,-17.7849776456127,8.01045312458763,-33.1259023133564,0.0291197576431311,-33.1258998671817,
9.481,0.0800000000000001,48,48,1,47.25,0,10.3045036261214,-0.0220957273025585,-22.0957273025585,10.3045074061214,-33.1290046204373,0.0172564026333048,-33.1290021742626,
9.491,0.0899999999999999,48,48,1,47.25,0,12.3554159590678,-0.0249609647349217,-24.9609647349217,12.3554197390678,-33.1323515221299,0.0240186045144492,-33.1323490759552,
9.501,0.0999999999999996,48,48,1,47.5,0,13.9466241443782,-0.0273936426241885,-27.3936426241885,13.9466279243782,-33.1337272335576,0.0246705933117596,-33.1337247873829,
9.511,0.110000000000001,48,48,1,47.5,0,14.9254928784515,-0.0299435102074668,-29.9435102074668,14.9254966584515,-33.1333634279147,0.0199066686978103,-33.1333609817399,
9.521,0.120000000000001,48,48,1,47.5,0,15.1773359843118,-0.0260405731204758,-26.0405731204758,15.1773397643118,-33.1324254819864,0.0200202440896454,-33.1324230358116,
9.531,0.130000000000001,48,48,1,47.5,0,14.8172618147988,-0.0289759416735494,-28.9759416735494,14.8172655947988,-33.1320228239358,0.0258168260692451,-33.132020377761,
9.541,0.140000000000001,48,48,1,47.5,0,13.7782806631724,-0.0290242520847935,-29.0242520847935,13.7782844431724,-33.1330870117828,0.0222466218341095,-33.133084565608,
9.551,0.15,48,48,1,47.75,0,12.0728065203541,-0.0261942550191243,-26.1942550191243,12.0728103003541,-33.133099330387,0.02173817161292,-33.1330968842123,
9.561,0.16,48,48,1,47.75,0,9.88377674049165,-0.0220829077906651,-22.0829077906651,9.88378052049166,-33.1346016233141,0.0253347269254698,-33.1345991771394,
9.571,0.17,48,48,1,47.75,0,7.4529764525493,-0.0174135372899437,-17.4135372899437,7.45298023254932,-33.1363125401963,0.0236937125883503,-33.1363100940215,
9.581,0.18,48,48,1,47.75,0,5.05835625011318,-0.0118098348025581,-11.8098348025581,5.05836003011319,-33.1328640392356,0.018251734744122,-33.1328615930608,
9.591,0.190000000000001,48,48,1,47.75,0,2.99727295415708,-0.0108645048704845,-10.8645048704845,2.99727673415707,-33.1298494534541,0.0216271738814722,-33.1298470072793,
9.601,0.200000000000001,48,48,1,48,0,1.40075837737042,-0.00771670114901251,-7.71670114901251,1.40076215737042,-33.1307489616891,0.0219462056325503,-33.1307465155143,
9.611,0.00999999999999979,49,49,1,48,0,0.431311701011256,-0.00591584469184299,-5.91584469184299,0.431315481011255,-33.1356022228642,0.0205048385939155,-33.1355997766895,
9.621,0.0199999999999996,49,49,1,48,0,0.187909221894466,-0.00803061325261743,-8.03061325261743,0.187913001894465,-33.138984704946,0.0220909621293607,-33.1389822587712,
9.63,0.0289999999999999,49,49,1,48,0,0.551491622808947,-0.00640098232420073,-6.40098232420073,0.551495402808947,-33.1386587273651,0.0231221696121682,-33.1386562811904,
9.64,0.0389999999999997,49,49,1,48,0,1.61926394682062,-0.00744022504739975,-7.44022504739975,1.61926772682062,-33.1351163592078,0.0192411894760994,-33.135113913033,
9.65,0.0489999999999995,49,49,1,48,0,3.3167551981635,-0.00974342508778396,-9.74342508778396,3.3167589781635,-33.1306940659708,0.0215437246034906,-33.1306916197961,
9.66,0.0589999999999993,49,49,1,48.25,0,5.47097329154646,-0.0152205460819321,-15.2205460819321,5.47097707154646,-33.1255394588276,0.0214047762633803,-33.1255370126528,
9.669,0.0679999999999996,49,49,1,48.25,0,7.55000469394146,-0.0178078531470519,-17.8078531470519,7.55000847394146,-33.1252203109443,0.0177450286102229,-33.1252178647695,
9.679,0.0779999999999994,49,49,1,48.25,0,9.86140011888156,-0.020967622409377,-20.967622409377,9.86140389888156,-33.1269705018935,0.0186980374381089,-33.1269680557188,
9.689,0.0879999999999992,49,49,1,48.25,0,11.9749082050143,-0.0238713539136062,-23.8713539136062,11.9749119850143,-33.1307826023408,0.025385713414718,-33.1307801561661,
9.699,0.097999999999999,49,49,1,48.25,0,13.6712960132121,-0.0270347478310896,-27.0347478310896,13.6712997932121,-33.1318732932654,0.0253576242213645,-33.1318708470906,
9.709,0.107999999999999,49,49,1,48.5,0,14.7790815921754,-0.0292035651541157,-29.2035651541157,14.7790853721754,-33.1323162193196,0.0208669132189488,-33.1323137731448,
9.718,0.116999999999999,49,49,1,48.5,0,15.170773131343,-0.0297881005317994,-29.7881005317994,15.170776911343,-33.1325004035535,0.0220614888121573,-33.1324979573787,
9.727,0.125999999999999,49,49,1,48.5,0,15.0277304801514,-0.0276687284033906,-27.6687284033906,15.0277342601514,-33.131875922215,0.019540744489236,-33.1318734760404,
9.737,0.135999999999999,49,49,1,48.5,0,14.2749872174271,-0.0288456083035804,-28.8456083035804,14.2749909974271,-33.1322009724585,0.0218580354661378,-33.1321985262838,
9.747,0.145999999999999,49,49,1,48.5,0,12.8260812867256,-0.0277919046880442,-27.7919046880442,12.8260850667256,-33.1322570458951,0.0260714644202633,-33.1322545997204,
9.757,0.155999999999999,49,49,1,48.75,0,10.805850376583,-0.0238609666403227,-23.8609666403227,10.805854156583,-33.1338445111168,0.0155698731368911,-33.1338420649421,
9.767,0.165999999999999,49,49,1,48.75,0,8.43734247888292,-0.0184586275843437,-18.4586275843437,8.43734625888291,-33.1367700667467,0.0217780493853733,-33.136767620572,
9.777,0.176,49,49,1,48.75,0,5.99569865199884,-0.0144099240728032,-14.4099240728032,5.99570243199883,-33.1348606444684,0.0226744831277204,-33.1348581982936,
9.786,0.184999999999999,49,49,1,48.75,0,3.97843370358005,-0.0116706886044633,-11.6706886044633,3.97843748358004,-33.1313665509107,0.0252122712669538,-33.1313641047359,
9.795,0.193999999999999,49,49,1,48.75,0,2.29543586061013,-0.00945672154369376,-9.45672154369377,2.29543964061013,-33.1301685856321,0.0269818143758449,-33.1301661394574,
9.805,0.00399999999999956,50,50,1,49,0,0.930146339997377,-0.00695023444491412,-6.95023444491412,0.930150119997376,-33.1320726292447,0.0201302562847978,-33.1320701830699,
9.814,0.0129999999999999,50,50,1,49,0,0.280784528948614,-0.00600345852815085,-6.00345852815085,0.280788308948614,-33.1357582521223,0.0228438938658133,-33.1357558059475,
9.823,0.0220000000000002,50,50,1,49,0,0.220901841753715,-0.00792603322300418,-7.92603322300418,0.220905621753715,-33.1391394043414,0.0204724498885765,-33.1391369581667,
9.833,0.032,50,50,1,49,0,0.798200598322148,-0.00686501989571701,-6.86501989571701,0.798204378322146,-33.139176602839,0.0181270090938484,-33.1391741566643,
9.843,0.0419999999999998,50,50,1,49,0,2.06379128503867,-0.00800535137464526,-8.00535137464526,2.06379506503867,-33.1351158223033,0.0212042662850583,-33.1351133761285,
9.853,0.0519999999999996,50,50,1,49.25,0,3.92183795981023,-0.0110462305726697,-11.0462305726697,3.92184173981023,-33.1301336100433,0.0235486108164658,-33.1301311638685,
9.863,0.0619999999999994,50,50,1,49.25,0,6.15688968561319,-0.0170062499827168,-17.0062499827168,6.1568934656132,-33.1271983512883,0.0163826694576232,-33.1271959051136,
9.871,0.0700000000000003,50,50,1,49.25,0,8.01383264487571,-0.0181685643451917,-18.1685643451917,8.01383642487569,-33.1266932809179,0.0313412746719223,-33.1266908347432,
9.881,0.0800000000000001,50,50,1,49.25,0,10.307788032944,-0.0221871498616027,-22.1871498616027,10.307791812944,-33.1288808341849,0.0170818585259697,-33.1288783880102,
9.891,0.0899999999999999,50,50,1,49.25,0,12.3564351658166,-0.0250663277560587,-25.0663277560587,12.3564389458166,-33.1335810336957,0.0200505689455243,-33.1335785875209,
9.901,0.0999999999999996,50,50,1,49.5,0,13.9446258314568,-0.0276161836240991,-27.6161836240991,13.9446296114568,-33.134769064829,0.0257424711291069,-33.1347666186543,
9.911,0.109999999999999,50,50,1,49.5,0,14.9210341675289,-0.0299847103654793,-29.9847103654793,14.9210379475289,-33.1340534669141,0.0216296435483554,-33.1340510207393,
9.919,0.118,50,50,1,49.5,0,15.1766539707117,-0.0290414318528804,-29.0414318528804,15.1766577507116,-33.1336848409083,0.0233892335148183,-33.1336823947335,
9.929,0.128,50,50,1,49.5,0,14.9338853559673,-0.0287104742877253,-28.7104742877253,14.9338891359673,-33.1333902518267,0.0224447820135603,-33.133387805652,
9.939,0.138,50,50,1,49.5,0,14.0381733325907,-0.0285862868423074,-28.5862868423074,14.0381771125907,-33.1335122695266,0.0213764497027361,-33.1335098233519,
9.949,0.148,50,50,1,49.5,0,12.4590478226022,-0.0267905706950852,-26.7905706950852,12.4590516026023,-33.1337677612673,0.0244516440381222,-33.1337653150925,
9.959,0.157999999999999,50,50,1,49.75,0,10.3510717078708,-0.0235043126539533,-23.5043126539533,10.3510754878709,-33.1351262777346,0.0238051231307395,-33.1351238315599,
9.969,0.167999999999999,50,50,1,49.75,0,7.94699267170591,-0.0180466960631605,-18.0466960631605,7.94699645170589,-33.1379490444419,0.0206348368405728,-33.1379465982672,
9.979,0.178000000000001,50,50,1,49.75,0,5.52223632164602,-0.0127772685289595,-12.7772685289595,5.52224010164602,-33.1357644187827,0.0227630538456946,-33.135761972608,
9.989,0.188000000000001,50,50,1,49.75,0,3.3784982678431,-0.0110639662195688,-11.0639662195688,3.3785020478431,-33.1345057462093,0.0270444492827344,-33.1345033000345,
9.999,0.198,50,50,1,49.75,0,1.67695113863184,-0.00820002274910358,-8.20002274910358,1.67695491863184,-33.1340035318903,0.0200679911006766,-33.1340010857156,
10.009,0.0080000000000009,51,51,1,50,0,0.568616796946912,-0.00650672356260655,-6.50672356260655,0.568620576946911,-33.1350479938421,0.020826504289641,-33.1350455476673,
10.018,0.0170000000000012,51,51,1,50,0,0.175757595901538,-0.00710184961880836,-7.10184961880836,0.175761375901538,-33.1346598921431,0.017935713489663,-33.1346574459684,
10.027,0.0260000000000016,51,51,1,50,0,0.316378245723464,-0.00785001661639942,-7.85001661639942,0.316382025723463,-33.1364543350211,0.0199520216611327,-33.1364518888464,
10.037,0.0360000000000014,51,51,1,50,0,1.05189691446093,-0.00941285976310571,-9.41285976310571,1.05190069446094,-33.1358576196645,0.0201636682362027,-33.1358551734898,
10.047,0.0460000000000012,51,51,1,50,0,2.31949990186669,-0.0116785871321413,-11.6785871321413,2.31950368186669,-33.1322955712896,0.0225805770451656,-33.1322931251148,
10.057,0.0560000000000009,51,51,1,50,0,3.94657611526469,-0.0162292610300861,-16.2292610300861,3.94657989526469,-33.12747939811,0.0174257848848506,-33.1274769519353,
10.066,0.0650000000000013,51,51,1,50,0,5.49587007736996,-0.0213896269914465,-21.3896269914465,5.49587385736996,-33.1247598431008,0.0214196879887494,-33.1247573969261,
10.076,0.0750000000000011,51,51,1,50,0,7.01909453801648,-0.024384986559592,-24.384986559592,7.0190983180165,-33.1257148266746,0.0244449854711169,-33.1257123804998,
10.086,0.0850000000000009,51,51,1,50,0,8.15890764789158,-0.0264458284712299,-26.4458284712299,8.15891142789158,-33.1262826234846,0.0233880366573935,-33.1262801773099,
10.096,0.0950000000000006,51,51,1,50,0,8.78753034439547,-0.0275866955513818,-27.5866955513818,8.78753412439547,-33.1262903135101,0.0225697410772643,-33.1262878673354,
10.106,0.105,51,51,1,50,0,8.84367410779034,-0.0257206422242304,-25.7206422242304,8.84367788779035,-33.1289240455894,0.0249305731045616,-33.1289215994147,
10.116,0.115,51,51,1,50,0,8.37930485424844,-0.0269130987843141,-26.9130987843141,8.37930863424843,-33.1323646298763,0.0218779125095465,-33.1323621837016,
10.125,0.124000000000001,51,51,1,50,0,7.49980894692715,-0.0254228789939811,-25.4228789939811,7.49981272692715,-33.1329757387563,0.0267640493954971,-33.1329732925815,
10.135,0.134,51,51,1,50,0,6.10631285004146,-0.0222943507859707,-22.2943507859707,6.10631663004146,-33.129924927924,0.0202039231140607,-33.1299224817493,
10.145,0.144,51,51,1,50,0,4.48478219129775,-0.0177060275466003,-17.7060275466003,4.48478597129775,-33.1274746887365,0.0223887360236357,-33.1274722425618,
10.155,0.154,51,51,1,50,0,2.8722805764914,-0.0164477034393931,-16.4477034393931,2.8722843564914,-33.1252603770584,0.0208179174298117,-33.1252579308837,
10.165,0.164000000000001,51,51,1,50,0,1.3866698782671,-0.0136888409794444,-13.6888409794444,1.38667365826711,-33.1275778722471,0.0207736881952347,-33.1275754260724,
10.175,0.174000000000001,51,51,1,50,0,0.175724542638554,-0.012335340569929,-12.335340569929,0.175728322638554,-33.1336329221092,0.0239560751873213,-33.1336304759345,
10.185,0.184000000000001,51,51,1,50,0,-0.656811456267901,-0.0114875161946328,-11.4875161946328,-0.656807676267901,-33.1371737797509,0.023494255638041,-33.1371713335762,
10.195,0.194000000000001,51,51,1,50,0,-1.0806293627927,-0.0122965998329393,-12.2965998329393,-1.08062558279269,-33.1389459009515,0.0204453172153051,-33.1389434547767,
10.204,0.203000000000001,51,51,1,50,0,-1.15861939326474,-0.015631655860942,-15.631655860942,-1.15861561326473,-33.140317068402,0.0210358584799684,-33.1403146222273,
10.214,0.213000000000001,51,51,1,50,0,-1.03672768172776,-0.0156289020273118,-15.6289020273118,-1.03672390172776,-33.1420837683867,0.0230327381627592,-33.142081322212,
10.224,0.223000000000001,51,51,1,50,0,-0.749432145810385,-0.0172132092285126,-17.2132092285126,-0.749428365810384,-33.1412794744632,0.0232275866592648,-33.1412770282884,
10.234,0.233000000000001,51,51,1,50,0,-0.391219454249677,-0.0188798858191901,-18.8798858191901,-0.391215674249678,-33.1388604256183,0.0222190073521417,-33.1388579794437,
10.244,0.243,51,51,1,50,0,-0.0538886369625295,-0.0203296845734803,-20.3296845734803,-0.0538848569625299,-33.137811324735,0.0219361644209853,-33.1378088785602,
10.254,0.253,51,51,1,50,0,0.189431563945129,-0.020381674478119,-20.381674478119,0.189435343945129,-33.136843187197,0.0220275403616749,-33.1368407410222,
10.264,0.263,51,51,1,50,0,0.312967956443816,-0.0206083794707585,-20.6083794707585,0.312971736443816,-33.1358766473581,0.0234418306377875,-33.1358742011833,
10.274,0.273000000000001,51,51,1,50,0,0.320032086571379,-0.0194072067281532,-19.4072067281532,0.32003586657138,-33.1358194031297,0.0236150499769717,-33.135816956955,
10.284,0.283000000000001,51,51,1,50,0,0.267405453785455,-0.0193819190499415,-19.3819190499415,0.267409233785455,-33.1352200635382,0.0211596714394844,-33.1352176173634,
10.294,0.293000000000001,51,51,1,50,0,0.170858485459888,-0.0187330772849535,-18.7330772849535,0.170862265459887,-33.1350266194039,0.0221795852486021,-33.1350241732291,
10.304,0.303000000000001,51,51,1,50,0,0.0583992456033204,-0.0181867186822934,-18.1867186822934,0.0584030256033201,-33.1347377892942,0.0211742672743338,-33.1347353431195,
10.314,0.313000000000001,51,51,1,50,0,-0.0375677112765486,-0.0177956656325119,-17.7956656325119,-0.0375639312765489,-33.1344300835551,0.0211599076916247,-33.1344276373803,
10.324,0.323,51,51,1,50,0,-0.0955568269601933,-0.017890580232425,-17.890580232425,-0.0955530469601936,-33.1357120505544,0.0240996159685239,-33.1357096043796,
10.33,0.000999999999999446,51,1,2,50,0,-0.10863784471931,-0.0179935130100316,-17.9935130100316,-0.10863406471931,-33.1365276889048,0.0240133205080966,-33.1365252427301,
10.387,0.0579999999999998,51,1,2,50,0,-0.109376258250558,-0.0186449351308815,-18.6449351308815,-0.109372478250559,-32.3674050937367,0.0675735099267378,-32.3674026475621,
10.444,0.115,51,1,2,50,0,-0.110550591252921,-0.0184514042862887,-18.4514042862887,-0.110546811252921,-27.1905425304186,0.0552652909809142,-27.1905400842438,
10.501,0.171999999999999,51,1,2,50,0.25,-0.111682904372849,-0.0185891954313294,-18.5891954313294,-0.111679124372849,-20.8220149509773,-0.0230741936099219,-20.8220125048026,
10.559,0.23,51,1,2,50,0.25,-0.111710148619234,-0.0186816021708299,-18.6816021708299,-0.111706368619235,-20.8655283535844,-0.107364687547466,-20.8655259074096,
10.609,0.279999999999999,51,1,2,50,0.5,-0.109203381909284,-0.0185599500785931,-18.5599500785931,-0.109199601909284,-30.8558919898195,0.0184202947249959,-30.8558895436447,
10.659,0.33,51,1,2,50,0.5,-0.10680385124651,-0.0184247956351487,-18.4247956351487,-0.106800071246511,-42.3673382592878,0.0483511576083991,-42.3673358131131,
10.715,0.385999999999999,51,1,2,50,0.75,-0.104659051027554,-0.018483464046924,-18.483464046924,-0.104655271027554,-50.9175429020332,0.0882735259935432,-50.9175404558586,
10.767,0.437999999999999,51,1,2,50,0.75,-0.104905805279005,-0.0186139137696139,-18.6139137696139,-0.104902025279006,-51.6555973327674,0.0952774797133578,-51.6555948865926,
10.823,0.494,51,1,2,50,0.75,-0.108059934583344,-0.0185448598689882,-18.5448598689882,-0.108056154583345,-43.8956886166191,0.031754902985818,-43.8956861704443,
10.873,0.544,51,1,2,50,1,-0.111991036345452,-0.0185520872331205,-18.5520872331205,-0.111987256345452,-32.5468452657163,0.0263704821277363,-32.5468428195415,
10.923,0.593999999999999,51,1,2,50,1,-0.114215003152227,-0.0185571376534021,-18.5571376534021,-0.114211223152228,-21.4515388171474,-0.00512098651287198,-21.4515363709727,
10.975,0.645999999999999,51,1,2,50,1.25,-0.116740542506121,-0.0184432827932187,-18.4432827932187,-0.116736762506122,-14.4353291534334,-0.0682647992606324,-14.4353267072586,
11.033,0.703999999999999,51,1,2,50,1.25,-0.116345674672266,-0.0184213058131697,-18.4213058131697,-0.116341894672266,-15.9130194400967,-0.0426017204026874,-15.913016993922,
11.083,0.754,51,1,2,50,1.5,-0.113878351354583,-0.0182583007496946,-18.2583007496946,-0.113874571354583,-24.1211351129695,-0.0337765271826353,-24.1211326667947,
11.133,0.804,51,1,2,50,1.5,-0.111030531149743,-0.0183507873044375,-18.3507873044375,-0.111026751149743,-36.3774501076087,0.0399495054449155,-36.377447661434,
11.183,0.853999999999999,51,1,2,50,1.5,-0.107129162750025,-0.0184613216011139,-18.4613216011139,-0.107125382750026,-46.9671503576387,0.0883723221603915,-46.967147911464,
11.245,0.916,51,1,2,50,1.75,-0.10582551239229,-0.0185809061452396,-18.5809061452396,-0.10582173239229,-52.1970512056497,0.0919619886871842,-52.197048759475,
11.303,0.974,51,1,2,50,1.75,-0.107267501669414,-0.0186561666295853,-18.6561666295853,-0.107263721669414,-47.5848214516543,0.0765613144571402,-47.5848190054796,
11.353,1.024,51,1,2,50,2,-0.110863946324371,-0.0185736510409601,-18.5736510409601,-0.110860166324372,-37.3936410471728,0.0451362985800413,-37.3936386009981,
11.403,1.074,51,1,2,50,2,-0.114048121861978,-0.0184618636544303,-18.4618636544303,-0.114044341861978,-25.5301091949348,-0.0196999818742766,-25.53010674876,
11.453,1.124,51,1,2,50,2,-0.116737068585064,-0.0185760560825352,-18.5760560825352,-0.116733288585064,-16.3946927435462,-0.0592568556787445,-16.3946902973714,
11.503,1.174,51,1,2,50,2.25,-0.116804895002871,-0.0183685610075684,-18.3685610075684,-0.116801115002871,-13.9821154827385,-0.0435108314086015,-13.9821130365638,
11.553,1.224,51,1,2,50,2.25,-0.115670020521808,-0.0183368170961501,-18.3368170961501,-0.115666240521809,-18.3703189026989,-0.0418474588618007,-18.3703164565241,
11.603,1.274,51,1,2,50,2.5,-0.11169506829617,-0.0185460525021921,-18.5460525021922,-0.11169128829617,-29.0180047825274,0.00186561716014833,-29.0180023363527,
11.653,1.324,51,1,2,50,2.5,-0.108430725381526,-0.0185113139526365,-18.5113139526365,-0.108426945381526,-40.9925030476544,0.0285743169905399,-40.9925006014796,
11.703,1.374,51,1,2,50,2.5,-0.105344439356736,-0.018691034917377,-18.691034917377,-0.105340659356737,-49.783440896923,0.0902552384632748,-49.7834384507483,
11.756,1.427,51,1,2,50,2.75,-0.104832080680471,-0.0185895715242672,-18.5895715242672,-0.104828300680472,-52.1703022784329,0.0814525515042771,-52.1702998322581,
11.812,1.483,51,1,2,50,2.75,-0.107639490185551,-0.0182693473635592,-18.2693473635592,-0.107635710185552,-46.0881712717818,0.0707278829952442,-46.0881688256071,
11.862,1.533,51,1,2,50,3,-0.110885253500249,-0.0184576494362825,-18.4576494362825,-0.110881473500249,-35.210772397967,0.0208714560803485,-35.2107699517923,
11.912,1.583,51,1,2,50,3,-0.113070523530626,-0.0185506577804378,-18.5506577804378,-0.113066743530627,-23.5836713466006,0.00697949994579305,-23.5836689004258,
11.965,1.636,51,1,2,50,3.25,-0.115823365110582,-0.0184418070618463,-18.4418070618463,-0.115819585110583,-15.0328851181545,-0.0557214449896402,-15.0328826719797,
12.023,1.694,51,1,2,50,3.25,-0.115580637790197,-0.0185461219675952,-18.5461219675952,-0.115576857790197,-14.941686045005,-0.0346998190901781,-14.9416835988302,
12.073,1.744,51,1,2,50,3.25,-0.113392716765337,-0.0183161962363424,-18.3161962363424,-0.113388936765338,-21.8874924447735,-0.0592172256629231,-21.8874899985987,
12.123,1.794,51,1,2,50,3.5,-0.109634204692009,-0.0186622001873984,-18.6622001873984,-0.109630424692009,-34.0270746292767,0.0375232872032553,-34.027072183102,
12.173,1.844,51,1,2,50,3.5,-0.10539633293983,-0.0183512152801541,-18.3512152801541,-0.10539255293983,-45.3200906800155,0.0850582798627454,-45.3200882338409,
12.229,1.9,51,1,2,50,3.75,-0.103704742176422,-0.0185207791906982,-18.5207791906982,-0.103700962176423,-51.9450710570392,0.0862213727595813,-51.9450686108646,
12.293,1.964,51,1,2,50,3.75,-0.104462762529123,-0.0187023487249986,-18.7023487249986,-0.104458982529123,-49.264309765095,0.0915742409954005,-49.2643073189203,
12.343,2.014,51,1,2,50,4,-0.10825784670825,-0.0185777357477156,-18.5777357477156,-0.10825406670825,-39.7898130023829,0.0567780924483315,-39.7898105562081,
12.393,2.064,51,1,2,50,4,-0.111501241582575,-0.0184536729973027,-18.4536729973027,-0.111497461582575,-27.7110748585877,-0.0133606728694293,-27.711072412413,
12.443,2.114,51,1,2,50,4,-0.114364876168117,-0.0186270882363246,-18.6270882363246,-0.114361096168117,-17.6908255770699,-0.0523106653202642,-17.6908231308952,
12.503,2.174,51,1,2,50,4.25,-0.11535044915643,-0.0184677383433787,-18.4677383433787,-0.11534666915643,-13.8657857353474,-0.0443551758047174,-13.8657832891727,
12.553,2.224,51,1,2,50,4.25,-0.114174130263656,-0.0184690963515858,-18.4690963515858,-0.114170350263656,-18.2904670965959,-0.0421775328828137,-18.2904646504211,
12.603,2.274,51,1,2,50,4.5,-0.11045579503718,-0.0184195641122789,-18.4195641122789,-0.11045201503718,-29.0018344332722,0.00090646681765429,-29.0018319870974,
12.653,2.324,51,1,2,50,4.5,-0.107043536665976,-0.0184288315930959,-18.4288315930959,-0.107039756665976,-41.0763457369367,0.0365791335365137,-41.0763432907619,
12.703,2.374,51,1,2,50,4.5,-0.103900101031784,-0.018577194948976,-18.577194948976,-0.103896321031784,-49.9092256543436,0.0893889956096507,-49.909223208169,
12.764,2.435,51,1,2,50,4.75,-0.103446979361218,-0.0186005635998009,-18.6005635998009,-0.103443199361218,-52.0423359539974,0.0900119103509437,-52.0423335078227,
12.814,2.485,51,1,2,50,4.75,-0.105864426872708,-0.0184653138410284,-18.4653138410284,-0.105860646872708,-45.8176379181263,0.0651263177874884,-45.8176354719515,
12.864,2.535,51,1,2,50,5,-0.109579284320177,-0.0185391063228849,-18.5391063228849,-0.109575504320178,-34.7406096804094,0.0246014992758429,-34.7406072342346,
12.914,2.585,51,1,2,50,5,-0.112372138587434,-0.0184900633915724,-18.4900633915724,-0.112368358587434,-23.1054048126721,0.0026993466713556,-23.1054023664973,
12.965,2.636,51,1,2,50,5.25,-0.115120603060842,-0.0183166514865808,-18.3166514865808,-0.115116823060842,-14.9130915352963,-0.0470190019869847,-14.9130890891216,
13.023,2.694,51,1,2,50,5.25,-0.114845527968989,-0.0184510541762977,-18.4510541762977,-0.114841747968989,-14.8411973628831,-0.0344494775698723,-14.8411949167083,
13.073,2.744,51,1,2,50,5.25,-0.11266180418002,-0.0185472188316667,-18.5472188316667,-0.11265802418002,-21.8280958495622,-0.0620003483215548,-21.8280934033875,
13.123,2.794,51,1,2,50,5.5,-0.109236829653215,-0.0183914456172595,-18.3914456172595,-0.109233049653215,-34.0390156512519,0.0393199509734838,-34.0390132050772,
13.173,2.844,51,1,2,50,5.5,-0.105091092857274,-0.0184755674284243,-18.4755674284243,-0.105087312857274,-45.411924439379,0.0985349290692025,-45.4119219932044,
13.225,2.896,51,1,2,50,5.75,-0.10333430925818,-0.0185154885034729,-18.5154885034729,-0.10333052925818,-51.8647378343988,0.0886115422281709,-51.8647353882242,
13.274,2.945,51,1,2,50,5.75,-0.103479542775398,-0.0187158587381,-18.7158587381,-0.103475762775398,-51.4929601551424,0.105215043652761,-51.4929577089678,
13.325,2.996,51,1,2,50,5.75,-0.106488549215135,-0.0184791224427149,-18.4791224427149,-0.106484769215135,-43.6944027271283,0.0276374439788679,-43.6944002809535,
13.375,3.046,51,1,2,50,6,-0.110048879786762,-0.0184040542117277,-18.4040542117277,-0.110045099786763,-32.0434268864544,0.0227157719167732,-32.0434244402797,
13.425,3.096,51,1,2,50,6,-0.112678897235951,-0.0183875077916493,-18.3875077916493,-0.112675117235952,-20.828534980616,-0.0109755953769559,-20.8285325344413,
13.475,3.146,51,1,2,50,6.25,-0.115147866483114,-0.0184992859759856,-18.4992859759856,-0.115144086483114,-14.1323486873255,-0.0706393485065595,-14.1323462411507,
13.533,3.204,51,1,2,50,6.25,-0.114572755342717,-0.0187583877675913,-18.7583877675913,-0.114568975342718,-15.6879531868852,-0.0349111110599921,-15.6879507407104,
13.583,3.254,51,1,2,50,6.5,-0.111832167503753,-0.0184218285534384,-18.4218285534384,-0.111828387503753,-24.0215518745345,-0.0385506591971817,-24.0215494283598,
13.633,3.304,51,1,2,50,6.5,-0.108801279182028,-0.0186046941071207,-18.6046941071207,-0.108797499182028,-36.4811708152588,0.0444195405151334,-36.481168369084,
13.683,3.354,51,1,2,50,6.5,-0.10477018975219,-0.0184300545776497,-18.4300545776497,-0.10476640975219,-47.2289993386328,0.0898513643087309,-47.228996892458,
13.735,3.406,51,1,2,50,6.75,-0.103515415825213,-0.0185521641992398,-18.5521641992398,-0.103511635825214,-52.3904364016215,0.089160431846674,-52.3904339554469,
13.786,3.457,51,1,2,50,6.75,-0.10404157246518,-0.0184738767537139,-18.4738767537139,-0.10403779246518,-50.370381964962,0.115544449741328,-50.3703795187872,
13.836,3.507,51,1,2,50,7,-0.107555818500238,-0.0184906799138833,-18.4906799138833,-0.107552038500239,-41.4362857250555,0.0906518775082139,-41.4362832788807,
13.886,3.557,51,1,2,50,7,-0.110936036365351,-0.0184966409346271,-18.4966409346271,-0.110932256365351,-29.3177013635138,-0.0119737165953819,-29.3176989173391,
13.936,3.607,51,1,2,50,7,-0.113884841373984,-0.0185813489855846,-18.5813489855846,-0.113881061373984,-18.7128098662536,-0.027759764898748,-18.7128074200789,
14.003,3.674,51,1,2,50,7.25,-0.115353575318115,-0.0184213396864066,-18.4213396864066,-0.115349795318115,-13.7177793619925,-0.0510451190589606,-13.7177769158178,
14.053,3.724,51,1,2,50,7.25,-0.114121379518325,-0.0184783288562973,-18.4783288562973,-0.114117599518325,-18.1967038659359,-0.0387809604457303,-18.1967014197612,
14.103,3.774,51,1,2,50,7.5,-0.110532476411004,-0.0184251812240534,-18.4251812240534,-0.110528696411004,-28.9826157780667,0.00793750611785932,-28.9826133318919,
14.153,3.824,51,1,2,50,7.5,-0.107070349491948,-0.018572545390901,-18.572545390901,-0.107066569491949,-41.1563169154017,0.035804134938967,-41.156314469227,
14.203,3.874,51,1,2,50,7.5,-0.104091588608175,-0.0186274003866228,-18.6274003866228,-0.104087808608175,-50.0592162648065,0.091175980578309,-50.0592138186318,
14.256,3.927,51,1,2,50,7.75,-0.103594289592664,-0.0186430255040216,-18.6430255040216,-0.103590509592664,-52.5063593273608,0.085524833393839,-52.5063568811861,
14.306,3.977,51,1,2,50,7.75,-0.105419831298108,-0.0185370225895418,-18.5370225895418,-0.105416051298108,-47.4056605023112,0.0758172438587031,-47.4056580561365,
14.356,4.027,51,1,2,50,8,-0.109158443920454,-0.0184803609226229,-18.4803609226229,-0.109154663920455,-36.741237718406,0.0337505590527477,-36.7412352722312,
14.406,4.077,51,1,2,50,8,-0.112311446473476,-0.0184629128592349,-18.4629128592349,-0.112307666473476,-24.7291340781374,-0.00529988797944045,-24.7291316319626,
14.456,4.127,51,1,2,50,8.25,-0.114971529939048,-0.0186438444404538,-18.6438444404538,-0.114967749939049,-15.7092368267857,-0.0633535105132979,-15.709234380611,
14.513,4.184,51,1,2,50,8.25,-0.115186953817502,-0.0185790942630149,-18.5790942630149,-0.115183173817502,-14.0731538879512,-0.0439322560349353,-14.0731514417765,
14.563,4.234,51,1,2,50,8.25,-0.113543437771429,-0.0184274042117001,-18.4274042117001,-0.11353965777143,-19.8266569559659,-0.0499119645573633,-19.8266545097912,
14.62,4.291,51,1,2,50,8.5,-0.109407417669282,-0.0185568316170387,-18.5568316170387,-0.109403637669283,-33.3020986003027,0.0376656062803241,-33.3020961541279,
14.67,4.341,51,1,2,50,8.5,-0.105478946274568,-0.0184867803293908,-18.4867803293908,-0.105475166274568,-44.9113894559183,0.0939755803728223,-44.9113870097435,
14.72,4.391,51,1,2,50,8.75,-0.103633528629955,-0.0187234610590206,-18.7234610590206,-0.103629748629956,-51.6957503824842,0.0836926305867224,-51.6957479363094,
14.776,4.447,51,1,2,50,8.75,-0.103764818851671,-0.0186126869888506,-18.6126869888506,-0.103761038851672,-51.4931350082494,0.10950288208977,-51.4931325620747,
14.825,4.496,51,1,2,50,8.75,-0.106675593277417,-0.0185632082482707,-18.5632082482707,-0.106671813277417,-43.77829524926,0.0356571251657416,-43.7782928030853,
14.88,4.551,51,1,2,50,9,-0.110517416793675,-0.0185253564654971,-18.5253564654971,-0.110513636793675,-30.7893667892137,0.0173762861496728,-30.789364343039,
14.93,4.601,51,1,2,50,9,-0.113261347513589,-0.01856890492847,-18.56890492847,-0.11325756751359,-19.7524663427384,-0.0131264933837637,-19.7524638965636,
14.98,4.651,51,1,2,50,9.25,-0.115235104500785,-0.0185838582538674,-18.5838582538674,-0.115231324500786,-13.7640822989399,-0.07402173338714,-13.7640798527652,
15.023,4.694,51,1,2,50,9.25,-0.114908030619615,-0.0185988694160488,-18.5988694160488,-0.114904250619615,-14.687284865807,-0.0370065274903469,-14.6872824196323,
15.073,4.744,51,1,2,50,9.25,-0.112595631314907,-0.018404925152579,-18.404925152579,-0.112591851314907,-21.7354612617435,-0.0625100322425012,-21.7354588155687,
15.13,4.801,51,1,2,50,9.5,-0.108779330479637,-0.0186304608538639,-18.6304608538639,-0.108775550479638,-35.7862785734951,0.0459399368781707,-35.7862761273204,
15.18,4.851,51,1,2,50,9.5,-0.104717824490353,-0.0185276168055366,-18.5276168055366,-0.104714044490354,-46.8217341124891,0.0834040393886799,-46.8217316663143,
15.23,4.901,51,1,2,50,9.75,-0.103334980242363,-0.0186786074965608,-18.6786074965608,-0.103331200242363,-52.3319753207904,0.0886930519983407,-52.3319728746156,
15.269,4.94,51,1,2,50,9.75,-0.103535916909761,-0.0188948979223005,-18.8948979223005,-0.103532136909761,-52.0384728025313,0.0968582653806014,-52.0384703563566,
15.319,4.99,51,1,2,50,9.75,-0.106202007792349,-0.018529137219821,-18.529137219821,-0.106198227792349,-45.0162361578712,0.0581643064162335,-45.0162337116966,
15.36,5.031,51,1,2,50,10,-0.109189342203475,-0.0185299488323665,-18.5299488323665,-0.109185562203476,-35.8866338385863,-0.00212326190539125,-35.8866313924115,
15.41,5.081,51,1,2,50,10,-0.111499782130559,-0.01856516164894,-18.56516164894,-0.111496002130559,-26.5880207120266,-0.0695614416391977,-26.5880182658518,
15.46,5.131,51,1,2,50,10,-0.11200090184835,-0.0184561758874267,-18.4561758874267,-0.11199712184835,-24.3130020006526,-0.0327066233042953,-24.3129995544779,
15.51,5.181,51,1,2,50,10,-0.111015355629154,-0.0185161982045385,-18.5161982045385,-0.111011575629154,-27.4232073912534,0.00632630782491696,-27.4232049450787,
15.56,5.231,51,1,2,50,10,-0.110116016135644,-0.0184201946400828,-18.4201946400828,-0.110112236135645,-31.6710956607234,0.0716529991386421,-31.6710932145486,
15.602,5.273,51,1,0,50,10,-0.109943043423233,-0.0184648291536005,-18.4648291536005,-0.109939263423233,-32.5710841008006,0.0309489447930838,-32.5710816546259,